Workbook

Sheet Controls
B2: PO SPEND TRACKER — CONTROLS
B3: Central assumptions. Blue cells on a cream fill are the only ones you edit. Everything else calculates.
B5: FY Start | C5: 45931 | D5: First day of the fiscal year (Oct 1). Drives every PO, vendor and monthly figure.
B6: FY End | C6: 46295 | D6: Last day of the fiscal year (Sep 30).
B7: Last Closed Month | C7: 46204 | D7: First day of the most recent CLOSED invoice month. Drives months elapsed, run-rate and projections.
B8: Watch Threshold | C8: 0.8 | D8: A PO at or above this % of its funds is flagged Watch.
B9: Trend Window (months) | C9: 3 | D9: How many trailing closed months feed the run-rate.
B10: Months Elapsed | C10: =(YEAR(Controls!$C$7)-YEAR(Controls!$C$5))*12+(MONTH(Controls!$C$7)-MONTH(Controls!$C$5))+1 -> 10 | D10: Closed months from FY Start through Last Closed Month.
B11: Months Remaining | C11: =12-Controls!$C$10 -> 2 | D11: Remaining months in the fiscal year.
B12: Trend Start | C12: =EDATE(Controls!$C$7,-(Controls!$C$9-1)) -> 46143 | D12: First month included in the trailing run-rate window.
B14: DATA COVERAGE (read-only)
B15: Latest invoice date in data | C15: =IFERROR(MAX(_MainTable!$G$2:$G$2001),0) -> 46252 | D15: Newest Invoice Date present on the Invoices tab. Keep Last Closed Month at or before this.
B16: Invoice rows loaded | C16: =COUNT(_MainTable!$G$2:$G$2001) -> 328 | D16: Rows on the Invoices tab with a usable Invoice Date.
B17: Change-order rows loaded | C17: =COUNT('SC Change Orders'!$C$2:$C$501) -> 36 | D17: Rows on the Change Orders tab with a usable Date Submitted.
B18: POs in this fiscal year | C18: =COUNT('PO Index'!$B$5:$B$84) -> 43 | D18: Distinct POs with activity between FY Start and FY End. The tracker sizes itself to this.
B19: Total invoiced this FY | C19: =SUMIFS(_MainTable!$K$2:$K$2001,_MainTable!$G$2:$G$2001,">="&Controls!$C$5,_MainTable!$G$2:$G$2001,"<="&Controls!$C$6) -> 13750125 | D19: Every FY invoice dollar, whether or not the PO carries a funding record.
B21: RANGE CAPACITY
B22: Wired range status | C22: =IF(OR(COUNT(_MainTable!$G$2:$G$2001)>=1979,COUNT('SC Change Orders'!$C$2:$C$501)>=479),"EXTEND RANGES","OK") -> OK | D22: Formulas read 2,000 invoice rows and 500 change-order rows. If a refresh ever pushes past that, this says EXTEND RANGES and the ranges need widening.
B24: HOW THE FUNDING NUMBERS ARE BUILT
B25: Starting Funds = smallest "Original Amount" on the PO's change orders inside the FY window (MINIFS).
B26: Total Funds Added = sum of "Amount Added" on the PO's change orders inside the FY window (SUMIFS).
B27: Total Available = Starting Funds + Total Funds Added.
B28: Spend to Date = sum of "Invoice $" on _MainTable for that PO, invoice-dated inside the FY window.
B29: Same definitions as the Data tab of Vendor_PO_Spending, so the figures tie to what you have today.
B30: Rows the change-order log records ambiguously are listed on the Data Quality tab.
B32: HOW TO CONNECT THIS TO YOUR LIVE POWER QUERIES
B33: This file is a working snapshot. To drive it from the live SharePoint queries instead:
B35: 1. Open Vendor_PO_Spending.xlsx (the workbook that holds the queries) alongside this one.
B36: 2. Here, click the "Controls" tab, then SHIFT-click "Data Quality" so all five tabs are selected together.
B37: Copying them in one go is what keeps the formulas between them intact.
... B47: full ownership detail. Nothing else needs changing — the PO list is driven by the data, not by a list.

Sheet PO Tracker
A1: PO SPEND TRACKER
A2: One row per PO with change-order or invoice activity between FY Start and FY End — the list builds itself, nothing here is typed. Funding comes from the Change Orders tab, spend from the Invoices tab. Run-rate is the trailing window from Controls, falling back to cumulative early in the year.
A4: Vendor | B4: PO | C4: Service | D4: Sr Leader | E4: Primary Owner | F4: Starting Funds | G4: Total Funds Added | H4: Total Available Funding | I4: Spend to Date | J4: Actual % of Funds | K4: Total Remaining | L4: Run-Rate / Mo | M4: Projected Add'l Spend | N4: Projected Total Spend | O4: Projected % of Funds | P4: Projected Over/(Under) | Q4: Mos to Depletion | R4: Status
A5: =IF($B5="","",IF((IFERROR(INDEX(_RefTable!$A$2:$A$501,MATCH($B5,_RefTable!$C$2:$C$501,0)),IFERROR(INDEX(_MainTable!$A$2:$A$2001,MATCH($B5,_MainTable!$F$2:$F$2001,0)),IFERROR(INDEX('SC Change Orders'!$A$2:$A$501,MATCH($B5,'SC Change Orders'!$B$2:$B$501,0)),"(unknown vendor)"))))&""="","—",(IFERROR(INDEX(_RefTable!$A$2:$A$501,MATCH($B5,_RefTable!$C$2:$C$501,0)),IFERROR(INDEX(_MainTable!$A$2:$A$2001,MATCH($B5,_MainTable!$F$2:$F$2001,0)),IFERROR(INDEX('SC Change Orders'!$A$2:$A$501,MATCH($B5,'SC Change Orders'!$B$2:$B$501,0)),"(unknown vendor)")))))) -> FMS INC | B5: =IFERROR(INDEX('PO Index'!$B$5:$B$84,1),"") -> 7892 | C5: =IF($B5="","",IF((IFERROR(INDEX(_RefTable!$B$2:$B$501,MATCH($B5,_RefTable!$C$2:$C$501,0))&IF(COUNTIF(_RefTable!$C$2:$C$501,$B5)>1," (+"&COUNTIF(_RefTable!$C$2:$C$501,$B5)-1&" more)",""),IFERROR(INDEX(_MainTable!$B$2:$B$2001,MATCH($B5,_MainTable!$F$2:$F$2001,0)),"")))&""="","—",(IFERROR(INDEX(_RefTable!$B$2:$B$501,MATCH($B5,_RefTable!$C$2:$C$501,0))&IF(COUNTIF(_RefTable!$C$2:$C$501,$B5)>1," (+"&COUNTIF(_RefTable!$C$2:$C$501,$B5)-1&" more)",""),IFERROR(INDEX(_MainTable!$B$2:$B$2001,MATCH($B5,_MainTable!$F$2:$F$2001,0)),""))))) -> McCall BD | D5: =IF($B5="","",IF((IFERROR(INDEX(_RefTable!$E$2:$E$501,MATCH($B5,_RefTable!$C$2:$C$501,0)),IFERROR(INDEX(_MainTable!$C$2:$C$2001,MATCH($B5,_MainTable!$F$2:$F$2001,0)),"")))&""="","—",(IFERROR(INDEX(_RefTable!$E$2:$E$501,MATCH($B5,_RefTable!$C$2:$C$501,0)),IFERROR(INDEX(_MainTable!$C$2:$C$2001,MATCH($B5,_MainTable!$F$2:$F$2001,0)),""))))) -> Jake Reid | E5: =IF($B5="","",IF((IFERROR(INDEX(_RefTable!$F$2:$F$501,MATCH($B5,_RefTable!$C$2:$C$501,0)),IFERROR(INDEX(_MainTable!$D$2:$D$2001,MATCH($B5,_MainTable!$F$2:$F$2001,0)),"")))&""="","—",(IFERROR(INDEX(_RefTable!$F$2:$F$501,MATCH($B5,_RefTable!$C$2:$C$501,0)),IFERROR(INDEX(_MainTable!$D$2:$D$2001,MATCH($B5,_MainTable!$F$2:$F$2001,0)),""))))) -> Letisia Speelman | F5: =IF($B5="","",IFERROR(_xlfn.MINIFS('SC Change Orders'!$E$2:$E$501,'SC Change Orders'!$B$2:$B$501,$B5,'SC Change Orders'!$C$2:$C$501,">="&Controls!$C$5,'SC Change Orders'!$C$2:$C$501,"<="&Controls!$C$6),0)) -> 0 | G5: =IF($B5="","",SUMIFS('SC Change Orders'!$F$2:$F$501,'SC Change Orders'!$B$2:$B$501,$B5,'SC Change Orders'!$C$2:$C$501,">="&Controls!$C$5,'SC Change Orders'!$C$2:$C$501,"<="&Controls!$C$6)) -> 0 | H5: =IF($B5="","",$F5+$G5) -> 0 | I5: =IF($B5="","",SUMIFS(_MainTable!$K$2:$K$2001,_MainTable!$F$2:$F$2001,$B5,_MainTable!$G$2:$G$2001,">="&Controls!$C$5,_MainTable!$G$2:$G$2001,"<="&Controls!$C$6)) -> 20.4 | J5: =IF($B5="","",IFERROR($I5/$H5,0)) -> 0 | K5: =IF($B5="","",$H5-$I5) -> -20.4 | L5: =IF($B5="","",IFERROR(SUMIFS(_MainTable!$K$2:$K$2001,_MainTable!$F$2:$F$2001,$B5,_MainTable!$G$2:$G$2001,">="&Controls!$C$12,_MainTable!$G$2:$G$2001,"<="&EOMONTH(Controls!$C$7,0))/MIN(Controls!$C$9,Controls!$C$10),0)) -> 3.4 | M5: =IF($B5="","",$L5*Controls!$C$11) -> 6.8 | N5: =IF($B5="","",$I5+$M5) -> 27.2 | O5: =IF($B5="","",IFERROR($N5/$H5,0)) -> 0 | P5: =IF($B5="","",$H5-$N5) -> -27.2 | Q5: =IF($B5="","",IF($L5<=0,"n/a",IFERROR($K5/$L5,"n/a"))) -> -6 | R5: =IF($B5="","",IF(AND($H5=0,$I5=0),"⚪ No Activity",IF(AND($H5=0,COUNTIFS('SC Change Orders'!$B$2:$B$501,$B5,'SC Change Orders'!$C$2:$C$501,">="&Controls!$C$5,'SC Change Orders'!$C$2:$C$501,"<="&Controls!$C$6)=0),"⚪ No Funding on File",IF($H5=0,"🔴 Unfunded Spend",IF($I5>=$H5,"🔴 Over Budget",IF($N5>$H5,"🔴 Projected Shortfall",IF($J5>=Controls!$C$8,"🟡 Watch","🟢 On Track"))))))) -> ⚪ No Funding on File
A6: =IF($B6="","",IF((IFERROR(INDEX(_RefTable!$A$2:$A$501,MATCH($B6,_RefTable!$C$2:$C$501,0)),IFERROR(INDEX(_MainTable!$A$2:$A$2001,MATCH($B6,_MainTable!$F$2:$F$2001,0)),IFERROR(INDEX('SC Change Orders'!$A$2:$A$501,MATCH($B6,'SC Change Orders'!$B$2:$B$501,0)),"(unknown vendor)"))))&""="","—",(IFERROR(INDEX(_RefTable!$A$2:$A$501,MATCH($B6,_RefTable!$C$2:$C$501,0)),IFERROR(INDEX(_MainTable!$A$2:$A$2001,MATCH($B6,_MainTable!$F$2:$F$2001,0)),IFERROR(INDEX('SC Change Orders'!$A$2:$A$501,MATCH($B6,'SC Change Orders'!$B$2:$B$501,0)),"(unknown vendor)")))))) -> FMS INC | B6: =IFERROR(INDEX('PO Index'!$B$5:$B$84,2),"") -> 7893 | C6: =IF($B6="","",IF((IFERROR(INDEX(_RefTable!$B$2:$B$501,MATCH($B6,_RefTable!$C$2:$C$501,0))&IF(COUNTIF(_RefTable!$C$2:$C$501,$B6)>1," (+"&COUNTIF(_RefTable!$C$2:$C$501,$B6)-1&" more)",""),IFERROR(INDEX(_MainTable!$B$2:$B$2001,MATCH($B6,_MainTable!$F$2:$F$2001,0)),"")))&""="","—",(IFERROR(INDEX(_RefTable!$B$2:$B$501,MATCH($B6,_RefTable!$C$2:$C$501,0))&IF(COUNTIF(_RefTable!$C$2:$C$501,$B6)>1," (+"&COUNTIF(_RefTable!$C$2:$C$501,$B6)-1&" more)",""),IFERROR(INDEX(_MainTable!$B$2:$B$2001,MATCH($B6,_MainTable!$F$2:$F$2001,0)),""))))) -> Base Recover | D6: =IF($B6="","",IF((IFERROR(INDEX(_RefTable!$E$2:$E$501,MATCH($B6,_RefTable!$C$2:$C$501,0)),IFERROR(INDEX(_MainTable!$C$2:$C$2001,MATCH($B6,_MainTable!$F$2:$F$2001,0)),"")))&""="","—",(IFERROR(INDEX(_RefTable!$E$2:$E$501,MATCH($B6,_RefTable!$C$2:$C$501,0)),IFERROR(INDEX(_MainTable!$C$2:$C$2001,MATCH($B6,_MainTable!$F$2:$F$2001,0)),""))))) -> Jake Reid | E6: =IF($B6="","",IF((IFERROR(INDEX(_RefTable!$F$2:$F$501,MATCH($B6,_RefTable!$C$2:$C$501,0)),IFERROR(INDEX(_MainTable!$D$2:$D$2001,MATCH($B6,_MainTable!$F$2:$F$2001,0)),"")))&""="","—",(IFERROR(INDEX(_RefTable!$F$2:$F$501,MATCH($B6,_RefTable!$C$2:$C$501,0)),IFERROR(INDEX(_MainTable!$D$2:$D$2001,MATCH($B6,_MainTable!$F$2:$F$2001,0)),""))))) -> Letisia Speelman | F6: =IF($B6="","",IFERROR(_xlfn.MINIFS('SC Change Orders'!$E$2:$E$501,'SC Change Orders'!$B$2:$B$501,$B6,'SC Change Orders'!$C$2:$C$501,">="&Controls!$C$5,'SC Change Orders'!$C$2:$C$501,"<="&Controls!$C$6),0)) -> 0 | G6: =IF($B6="","",SUMIFS('SC Change Orders'!$F$2:$F$501,'SC Change Orders'!$B$2:$B$501,$B6,'SC Change Orders'!$C$2:$C$501,">="&Controls!$C$5,'SC Change Orders'!$C$2:$C$501,"<="&Controls!$C$6)) -> 0 | H6: =IF($B6="","",$F6+$G6) -> 0 | I6: =IF($B6="","",SUMIFS(_MainTable!$K$2:$K$2001,_MainTable!$F$2:$F$2001,$B6,_MainTable!$G$2:$G$2001,">="&Controls!$C$5,_MainTable!$G$2:$G$2001,"<="&Controls!$C$6)) -> 219.85 | J6: =IF($B6="","",IFERROR($I6/$H6,0)) -> 0 | K6: =IF($B6="","",$H6-$I6) -> -219.85 | L6: =IF($B6="","",IFERROR(SUMIFS(_MainTable!$K$2:$K$2001,_MainTable!$F$2:$F$2001,$B6,_MainTable!$G$2:$G$2001,">="&Controls!$C$12,_MainTable!$G$2:$G$2001,"<="&EOMONTH(Controls!$C$7,0))/MIN(Controls!$C$9,Controls!$C$10),0)) -> 29.546667 | M6: =IF($B6="","",$L6*Controls!$C$11) -> 59.093333 | N6: =IF($B6="","",$I6+$M6) -> 278.94333 | O6: =IF($B6="","",IFERROR($N6/$H6,0)) -> 0 | P6: =IF($B6="","",$H6-$N6) -> -278.94333 | Q6: =IF($B6="","",IF($L6<=0,"n/a",IFERROR($K6/$L6,"n/a"))) -> -7.4407717 | R6: =IF($B6="","",IF(AND($H6=0,$I6=0),"⚪ No Activity",IF(AND($H6=0,COUNTIFS('SC Change Orders'!$B$2:$B$501,$B6,'SC Change Orders'!$C$2:$C$501,">="&Controls!$C$5,'SC Change Orders'!$C$2:$C$501,"<="&Controls!$C$6)=0),"⚪ No Funding on File",IF($H6=0,"🔴 Unfunded Spend",IF($I6>=$H6,"🔴 Over Budget",IF($N6>$H6,"🔴 Projected Shortfall",IF($J6>=Controls!$C$8,"🟡 Watch","🟢 On Track"))))))) -> ⚪ No Funding on File
A7: =IF($B7="","",IF((IFERROR(INDEX(_RefTable!$A$2:$A$501,MATCH($B7,_RefTable!$C$2:$C$501,0)),IFERROR(INDEX(_MainTable!$A$2:$A$2001,MATCH($B7,_MainTable!$F$2:$F$2001,0)),IFERROR(INDEX('SC Change Orders'!$A$2:$A$501,MATCH($B7,'SC Change Orders'!$B$2:$B$501,0)),"(unknown vendor)"))))&""="","—",(IFERROR(INDEX(_RefTable!$A$2:$A$501,MATCH($B7,_RefTable!$C$2:$C$501,0)),IFERROR(INDEX(_MainTable!$A$2:$A$2001,MATCH($B7,_MainTable!$F$2:$F$2001,0)),IFERROR(INDEX('SC Change Orders'!$A$2:$A$501,MATCH($B7,'SC Change Orders'!$B$2:$B$501,0)),"(unknown vendor)")))))) -> FMS INC | B7: =IFERROR(INDEX('PO Index'!$B$5:$B$84,3),"") -> 7894 | C7: =IF($B7="","",IF((IFERROR(INDEX(_RefTable!$B$2:$B$501,MATCH($B7,_RefTable!$C$2:$C$501,0))&IF(COUNTIF(_RefTable!$C$2:$C$501,$B7)>1," (+"&COUNTIF(_RefTable!$C$2:$C$501,$B7)-1&" more)",""),IFERROR(INDEX(_MainTable!$B$2:$B$2001,MATCH($B7,_MainTable!$F$2:$F$2001,0)),"")))&""="","—",(IFERROR(INDEX(_RefTable!$B$2:$B$501,MATCH($B7,_RefTable!$C$2:$C$501,0))&IF(COUNTIF(_RefTable!$C$2:$C$501,$B7)>1," (+"&COUNTIF(_RefTable!$C$2:$C$501,$B7)-1&" more)",""),IFERROR(INDEX(_MainTable!$B$2:$B$2001,MATCH($B7,_MainTable!$F$2:$F$2001,0)),""))))) -> Skim Overflow | D7: =IF($B7="","",IF((IFERROR(INDEX(_RefTable!$E$2:$E$501,MATCH($B7,_RefTable!$C$2:$C$501,0)),IFERROR(INDEX(_MainTable!$C$2:$C$2001,MATCH($B7,_MainTable!$F$2:$F$2001,0)),"")))&""="","—",(IFERROR(INDEX(_RefTable!$E$2:$E$501,MATCH($B7,_RefTable!$C$2:$C$501,0)),IFERROR(INDEX(_MainTable!$C$2:$C$2001,MATCH($B7,_MainTable!$F$2:$F$2001,0)),""))))) -> Jake Reid | E7: =IF($B7="","",IF((IFERROR(INDEX(_RefTable!$F$2:$F$501,MATCH($B7,_RefTable!$C$2:$C$501,0)),IFERROR(INDEX(_MainTable!$D$2:$D$2001,MATCH($B7,_MainTable!$F$2:$F$2001,0)),"")))&""="","—",(IFERROR(INDEX(_RefTable!$F$2:$F$501,MATCH($B7,_RefTable!$C$2:$C$501,0)),IFERROR(INDEX(_MainTable!$D$2:$D$2001,MATCH($B7,_MainTable!$F$2:$F$2001,0)),""))))) -> Letisia Speelman | F7: =IF($B7="","",IFERROR(_xlfn.MINIFS('SC Change Orders'!$E$2:$E$501,'SC Change Orders'!$B$2:$B$501,$B7,'SC Change Orders'!$C$2:$C$501,">="&Controls!$C$5,'SC Change Orders'!$C$2:$C$501,"<="&Controls!$C$6),0)) -> 0 | G7: =IF($B7="","",SUMIFS('SC Change Orders'!$F$2:$F$501,'SC Change Orders'!$B$2:$B$501,$B7,'SC Change Orders'!$C$2:$C$501,">="&Controls!$C$5,'SC Change Orders'!$C$2:$C$501,"<="&Controls!$C$6)) -> 0 | H7: =IF($B7="","",$F7+$G7) -> 0 | I7: =IF($B7="","",SUMIFS(_MainTable!$K$2:$K$2001,_MainTable!$F$2:$F$2001,$B7,_MainTable!$G$2:$G$2001,">="&Controls!$C$5,_MainTable!$G$2:$G$2001,"<="&Controls!$C$6)) -> 50650.61 | J7: =IF($B7="","",IFERROR($I7/$H7,0)) -> 0 | K7: =IF($B7="","",$H7-$I7) -> -50650.61 | L7: =IF($B7="","",IFERROR(SUMIFS(_MainTable!$K$2:$K$2001,_MainTable!$F$2:$F$2001,$B7,_MainTable!$G$2:$G$2001,">="&Controls!$C$12,_MainTable!$G$2:$G$2001,"<="&EOMONTH(Controls!$C$7,0))/MIN(Controls!$C$9,Controls!$C$10),0)) -> 9042.36 | M7: =IF($B7="","",$L7*Controls!$C$11) -> 18084.72 | N7: =IF($B7="","",$I7+$M7) -> 68735.33 | O7: =IF($B7="","",IFERROR($N7/$H7,0)) -> 0 | P7: =IF($B7="","",$H7-$N7) -> -68735.33 | Q7: =IF($B7="","",IF($L7<=0,"n/a",IFERROR($K7/$L7,"n/a"))) -> -5.6014813 | R7: =IF($B7="","",IF(AND($H7=0,$I7=0),"⚪ No Activity",IF(AND($H7=0,COUNTIFS('SC Change Orders'!$B$2:$B$501,$B7,'SC Change Orders'!$C$2:$C$501,">="&Controls!$C$5,'SC Change Orders'!$C$2:$C$501,"<="&Controls!$C$6)=0),"⚪ No Funding on File",IF($H7=0,"🔴 Unfunded Spend",IF($I7>=$H7,"🔴 Over Budget",IF($N7>$H7,"🔴 Projected Shortfall",IF($J7>=Controls!$C$8,"🟡 Watch","🟢 On Track"))))))) -> ⚪ No Funding on File
A8: =IF($B8="","",IF((IFERROR(INDEX(_RefTable!$A$2:$A$501,MATCH($B8,_RefTable!$C$2:$C$501,0)),IFERROR(INDEX(_MainTable!$A$2:$A$2001,MATCH($B8,_MainTable!$F$2:$F$2001,0)),IFERROR(INDEX('SC Change Orders'!$A$2:$A$501,MATCH($B8,'SC Change Orders'!$B$2:$B$501,0)),"(unknown vendor)"))))&""="","—",(IFERROR(INDEX(_RefTable!$A$2:$A$501,MATCH($B8,_RefTable!$C$2:$C$501,0)),IFERROR(INDEX(_MainTable!$A$2:$A$2001,MATCH($B8,_MainTable!$F$2:$F$2001,0)),IFERROR(INDEX('SC Change Orders'!$A$2:$A$501,MATCH($B8,'SC Change Orders'!$B$2:$B$501,0)),"(unknown vendor)")))))) -> FMS INC | B8: =IFERROR(INDEX('PO Index'!$B$5:$B$84,4),"") -> 7896 | C8: =IF($B8="","",IF((IFERROR(INDEX(_RefTable!$B$2:$B$501,MATCH($B8,_RefTable!$C$2:$C$501,0))&IF(COUNTIF(_RefTable!$C$2:$C$501,$B8)>1," (+"&COUNTIF(_RefTable!$C$2:$C$501,$B8)-1&" more)",""),IFERROR(INDEX(_MainTable!$B$2:$B$2001,MATCH($B8,_MainTable!$F$2:$F$2001,0)),"")))&""="","—",(IFERROR(INDEX(_RefTable!$B$2:$B$501,MATCH($B8,_RefTable!$C$2:$C$501,0))&IF(COUNTIF(_RefTable!$C$2:$C$501,$B8)>1," (+"&COUNTIF(_RefTable!$C$2:$C$501,$B8)-1&" more)",""),IFERROR(INDEX(_MainTable!$B$2:$B$2001,MATCH($B8,_MainTable!$F$2:$F$2001,0)),""))))) -> MV EBO | D8: =IF($B8="","",IF((IFERROR(INDEX(_RefTable!$E$2:$E$501,MATCH($B8,_RefTable!$C$2:$C$501,0)),IFERROR(INDEX(_MainTable!$C$2:$C$2001,MATCH($B8,_MainTable!$F$2:$F$2001,0)),"")))&""="","—",(IFERROR(INDEX(_RefTable!$E$2:$E$501,MATCH($B8,_RefTable!$C$2:$C$501,0)),IFERROR(INDEX(_MainTable!$C$2:$C$2001,MATCH($B8,_MainTable!$F$2:$F$2001,0)),""))))) -> Jake Reid | E8: =IF($B8="","",IF((IFERROR(INDEX(_RefTable!$F$2:$F$501,MATCH($B8,_RefTable!$C$2:$C$501,0)),IFERROR(INDEX(_MainTable!$D$2:$D$2001,MATCH($B8,_MainTable!$F$2:$F$2001,0)),"")))&""="","—",(IFERROR(INDEX(_RefTable!$F$2:$F$501,MATCH($B8,_RefTable!$C$2:$C$501,0)),IFERROR(INDEX(_MainTable!$D$2:$D$2001,MATCH($B8,_MainTable!$F$2:$F$2001,0)),""))))) -> Letisia Speelman | F8: =IF($B8="","",IFERROR(_xlfn.MINIFS('SC Change Orders'!$E$2:$E$501,'SC Change Orders'!$B$2:$B$501,$B8,'SC Change Orders'!$C$2:$C$501,">="&Controls!$C$5,'SC Change Orders'!$C$2:$C$501,"<="&Controls!$C$6),0)) -> 0 | G8: =IF($B8="","",SUMIFS('SC Change Orders'!$F$2:$F$501,'SC Change Orders'!$B$2:$B$501,$B8,'SC Change Orders'!$C$2:$C$501,">="&Controls!$C$5,'SC Change Orders'!$C$2:$C$501,"<="&Controls!$C$6)) -> 0 | H8: =IF($B8="","",$F8+$G8) -> 0 | I8: =IF($B8="","",SUMIFS(_MainTable!$K$2:$K$2001,_MainTable!$F$2:$F$2001,$B8,_MainTable!$G$2:$G$2001,">="&Controls!$C$5,_MainTable!$G$2:$G$2001,"<="&Controls!$C$6)) -> 462.43 | J8: =IF($B8="","",IFERROR($I8/$H8,0)) -> 0 | K8: =IF($B8="","",$H8-$I8) -> -462.43 | L8: =IF($B8="","",IFERROR(SUMIFS(_MainTable!$K$2:$K$2001,_MainTable!$F$2:$F$2001,$B8,_MainTable!$G$2:$G$2001,">="&Controls!$C$12,_MainTable!$G$2:$G$2001,"<="&EOMONTH(Controls!$C$7,0))/MIN(Controls!$C$9,Controls!$C$10),0)) -> 89.68 | M8: =IF($B8="","",$L8*Controls!$C$11) -> 179.36 | N8: =IF($B8="","",$I8+$M8) -> 641.79 | O8: =IF($B8="","",IFERROR($N8/$H8,0)) -> 0 | P8: =IF($B8="","",$H8-$N8) -> -641.79 | Q8: =IF($B8="","",IF($L8<=0,"n/a",IFERROR($K8/$L8,"n/a"))) -> -5.1564451 | R8: =IF($B8="","",IF(AND($H8=0,$I8=0),"⚪ No Activity",IF(AND($H8=0,COUNTIFS('SC Change Orders'!$B$2:$B$501,$B8,'SC Change Orders'!$C$2:$C$501,">="&Controls!$C$5,'SC Change Orders'!$C$2:$C$501,"<="&Controls!$C$6)=0),"⚪ No Funding on File",IF($H8=0,"🔴 Unfunded Spend",IF($I8>=$H8,"🔴 Over Budget",IF($N8>$H8,"🔴 Projected Shortfall",IF($J8>=Controls!$C$8,"🟡 Watch","🟢 On Track"))))))) -> ⚪ No Funding on File
A9: =IF($B9="","",IF((IFERROR(INDEX(_RefTable!$A$2:$A$501,MATCH($B9,_RefTable!$C$2:$C$501,0)),IFERROR(INDEX(_MainTable!$A$2:$A$2001,MATCH($B9,_MainTable!$F$2:$F$2001,0)),IFERROR(INDEX('SC Change Orders'!$A$2:$A$501,MATCH($B9,'SC Change Orders'!$B$2:$B$501,0)),"(unknown vendor)"))))&""="","—",(IFERROR(INDEX(_RefTable!$A$2:$A$501,MATCH($B9,_RefTable!$C$2:$C$501,0)),IFERROR(INDEX(_MainTable!$A$2:$A$2001,MATCH($B9,_MainTable!$F$2:$F$2001,0)),IFERROR(INDEX('SC Change Orders'!$A$2:$A$501,MATCH($B9,'SC Change Orders'!$B$2:$B$501,0)),"(unknown vendor)")))))) -> FORTE LLC | B9: =IFERROR(INDEX('PO Index'!$B$5:$B$84,5),"") -> 7910 | C9: =IF($B9="","",IF((IFERROR(INDEX(_RefTable!$B$2:$B$501,MATCH($B9,_RefTable!$C$2:$C$501,0))&IF(COUNTIF(_RefTable!$C$2:$C$501,$B9)>1," (+"&COUNTIF(_RefTable!$C$2:$C$501,$B9)-1&" more)",""),IFERROR(INDEX(_MainTable!$B$2:$B$2001,MATCH($B9,_MainTable!$F$2:$F$2001,0)),"")))&""="","—",(IFERROR(INDEX(_RefTable!$B$2:$B$501,MATCH($B9,_RefTable!$C$2:$C$501,0))&IF(COUNTIF(_RefTable!$C$2:$C$501,$B9)>1," (+"&COUNTIF(_RefTable!$C$2:$C$501,$B9)-1&" more)",""),IFERROR(INDEX(_MainTable!$B$2:$B$2001,MATCH($B9,_MainTable!$F$2:$F$2001,0)),""))))) -> Probate Finder | D9: =IF($B9="","",IF((IFERROR(INDEX(_RefTable!$E$2:$E$501,MATCH($B9,_RefTable!$C$2:$C$501,0)),IFERROR(INDEX(_MainTable!$C$2:$C$2001,MATCH($B9,_MainTable!$F$2:$F$2001,0)),"")))&""="","—",(IFERROR(INDEX(_RefTable!$E$2:$E$501,MATCH($B9,_RefTable!$C$2:$C$501,0)),IFERROR(INDEX(_MainTable!$C$2:$C$2001,MATCH($B9,_MainTable!$F$2:$F$2001,0)),""))))) -> Jake Reid | E9: =IF($B9="","",IF((IFERROR(INDEX(_RefTable!$F$2:$F$501,MATCH($B9,_RefTable!$C$2:$C$501,0)),IFERROR(INDEX(_MainTable!$D$2:$D$2001,MATCH($B9,_MainTable!$F$2:$F$2001,0)),"")))&""="","—",(IFERROR(INDEX(_RefTable!$F$2:$F$501,MATCH($B9,_RefTable!$C$2:$C$501,0)),IFERROR(INDEX(_MainTable!$D$2:$D$2001,MATCH($B9,_MainTable!$F$2:$F$2001,0)),""))))) -> Letisia Speelman | F9: =IF($B9="","",IFERROR(_xlfn.MINIFS('SC Change Orders'!$E$2:$E$501,'SC Change Orders'!$B$2:$B$501,$B9,'SC Change Orders'!$C$2:$C$501,">="&Controls!$C$5,'SC Change Orders'!$C$2:$C$501,"<="&Controls!$C$6),0)) -> 0 | G9: =IF($B9="","",SUMIFS('SC Change Orders'!$F$2:$F$501,'SC Change Orders'!$B$2:$B$501,$B9,'SC Change Orders'!$C$2:$C$501,">="&Controls!$C$5,'SC Change Orders'!$C$2:$C$501,"<="&Controls!$C$6)) -> 0 | H9: =IF($B9="","",$F9+$G9) -> 0 | I9: =IF($B9="","",SUMIFS(_MainTable!$K$2:$K$2001,_MainTable!$F$2:$F$2001,$B9,_MainTable!$G$2:$G$2001,">="&Controls!$C$5,_MainTable!$G$2:$G$2001,"<="&Controls!$C$6)) -> 18414.44 | J9: =IF($B9="","",IFERROR($I9/$H9,0)) -> 0 | K9: =IF($B9="","",$H9-$I9) -> -18414.44 | L9: =IF($B9="","",IFERROR(SUMIFS(_MainTable!$K$2:$K$2001,_MainTable!$F$2:$F$2001,$B9,_MainTable!$G$2:$G$2001,">="&Controls!$C$12,_MainTable!$G$2:$G$2001,"<="&EOMONTH(Controls!$C$7,0))/MIN(Controls!$C$9,Controls!$C$10),0)) -> 2274.2833 | M9: =IF($B9="","",$L9*Controls!$C$11) -> 4548.5667 | N9: =IF($B9="","",$I9+$M9) -> 22963.007 | O9: =IF($B9="","",IFERROR($N9/$H9,0)) -> 0 | P9: =IF($B9="","",$H9-$N9) -> -22963.007 | Q9: =IF($B9="","",IF($L9<=0,"n/a",IFERROR($K9/$L9,"n/a"))) -> -8.09681 | R9: =IF($B9="","",IF(AND($H9=0,$I9=0),"⚪ No Activity",IF(AND($H9=0,COUNTIFS('SC Change Orders'!$B$2:$B$501,$B9,'SC Change Orders'!$C$2:$C$501,">="&Controls!$C$5,'SC Change Orders'!$C$2:$C$501,"<="&Controls!$C$6)=0),"⚪ No Funding on File",IF($H9=0,"🔴 Unfunded Spend",IF($I9>=$H9,"🔴 Over Budget",IF($N9>$H9,"🔴 Projected Shortfall",IF($J9>=Controls!$C$8,"🟡 Watch","🟢 On Track"))))))) -> ⚪ No Funding on File
A10: =IF($B10="","",IF((IFERROR(INDEX(_RefTable!$A$2:$A$501,MATCH($B10,_RefTable!$C$2:$C$501,0)),IFERROR(INDEX(_MainTable!$A$2:$A$2001,MATCH($B10,_MainTable!$F$2:$F$2001,0)),IFERROR(INDEX('SC Change Orders'!$A$2:$A$501,MATCH($B10,'SC Change Orders'!$B$2:$B$501,0)),"(unknown vendor)"))))&""="","—",(IFERROR(INDEX(_RefTable!$A$2:$A$501,MATCH($B10,_RefTable!$C$2:$C$501,0)),IFERROR(INDEX(_MainTable!$A$2:$A$2001,MATCH($B10,_MainTable!$F$2:$F$2001,0)),IFERROR(INDEX('SC Change Orders'!$A$2:$A$501,MATCH($B10,'SC Change Orders'!$B$2:$B$501,0)),"(unknown vendor)")))))) -> HAWLEY TROXELL ENNIS HAWLEY | B10: =IFERROR(INDEX('PO Index'!$B$5:$B$84,6),"") -> 7911 | C10: =IF($B10="","",IF((IFERROR(INDEX(_RefTable!$B$2:$B$501,MATCH($B10,_RefTable!$C$2:$C$501,0))&IF(COUNTIF(_RefTable!$C$2:$C$501,$B10)>1," (+"&COUNTIF(_RefTable!$C$2:$C$501,$B10)-1&" more)",""),IFERROR(INDEX(_MainTable!$B$2:$B$2001,MATCH($B10,_MainTable!$F$2:$F$2001,0)),"")))&""="","—",(IFERROR(INDEX(_RefTable!$B$2:$B$501,MATCH($B10,_RefTable!$C$2:$C$501,0))&IF(COUNTIF(_RefTable!$C$2:$C$501,$B10)>1," (+"&COUNTIF(_RefTable!$C$2:$C$501,$B10)-1&" more)",""),IFERROR(INDEX(_MainTable!$B$2:$B$2001,MATCH($B10,_MainTable!$F$2:$F$2001,0)),""))))) -> Estate/Probate (+1 more) | D10: =IF($B10="","",IF((IFERROR(INDEX(_RefTable!$E$2:$E$501,MATCH($B10,_RefTable!$C$2:$C$501,0)),IFERROR(INDEX(_MainTable!$C$2:$C$2001,MATCH($B10,_MainTable!$F$2:$F$2001,0)),"")))&""="","—",(IFERROR(INDEX(_RefTable!$E$2:$E$501,MATCH($B10,_RefTable!$C$2:$C$501,0)),IFERROR(INDEX(_MainTable!$C$2:$C$2001,MATCH($B10,_MainTable!$F$2:$F$2001,0)),""))))) -> Jake Reid | E10: =IF($B10="","",IF((IFERROR(INDEX(_RefTable!$F$2:$F$501,MATCH($B10,_RefTable!$C$2:$C$501,0)),IFERROR(INDEX(_MainTable!$D$2:$D$2001,MATCH($B10,_MainTable!$F$2:$F$2001,0)),"")))&""="","—",(IFERROR(INDEX(_RefTable!$F$2:$F$501,MATCH($B10,_RefTable!$C$2:$C$501,0)),IFERROR(INDEX(_MainTable!$D$2:$D$2001,MATCH($B10,_MainTable!$F$2:$F$2001,0)),""))))) -> Letisia Speelman | F10: =IF($B10="","",IFERROR(_xlfn.MINIFS('SC Change Orders'!$E$2:$E$501,'SC Change Orders'!$B$2:$B$501,$B10,'SC Change Orders'!$C$2:$C$501,">="&Controls!$C$5,'SC Change Orders'!$C$2:$C$501,"<="&Controls!$C$6),0)) -> 0 | G10: =IF($B10="","",SUMIFS('SC Change Orders'!$F$2:$F$501,'SC Change Orders'!$B$2:$B$501,$B10,'SC Change Orders'!$C$2:$C$501,">="&Controls!$C$5,'SC Change Orders'!$C$2:$C$501,"<="&Controls!$C$6)) -> 0 | H10: =IF($B10="","",$F10+$G10) -> 0 | I10: =IF($B10="","",SUMIFS(_MainTable!$K$2:$K$2001,_MainTable!$F$2:$F$2001,$B10,_MainTable!$G$2:$G$2001,">="&Controls!$C$5,_MainTable!$G$2:$G$2001,"<="&Controls!$C$6)) -> 7945.44 | J10: =IF($B10="","",IFERROR($I10/$H10,0)) -> 0 | K10: =IF($B10="","",$H10-$I10) -> -7945.44 | L10: =IF($B10="","",IFERROR(SUMIFS(_MainTable!$K$2:$K$2001,_MainTable!$F$2:$F$2001,$B10,_MainTable!$G$2:$G$2001,">="&Controls!$C$12,_MainTable!$G$2:$G$2001,"<="&EOMONTH(Controls!$C$7,0))/MIN(Controls!$C$9,Controls!$C$10),0)) -> 2466.1667 | M10: =IF($B10="","",$L10*Controls!$C$11) -> 4932.3333 | N10: =IF($B10="","",$I10+$M10) -> 12877.773 | O10: =IF($B10="","",IFERROR($N10/$H10,0)) -> 0 | P10: =IF($B10="","",$H10-$N10) -> -12877.773 | Q10: =IF($B10="","",IF($L10<=0,"n/a",IFERROR($K10/$L10,"n/a"))) -> -3.2217774 | R10: =IF($B10="","",IF(AND($H10=0,$I10=0),"⚪ No Activity",IF(AND($H10=0,COUNTIFS('SC Change Orders'!$B$2:$B$501,$B10,'SC Change Orders'!$C$2:$C$501,">="&Controls!$C$5,'SC Change Orders'!$C$2:$C$501,"<="&Controls!$C$6)=0),"⚪ No Funding on File",IF($H10=0,"🔴 Unfunded Spend",IF($I10>=$H10,"🔴 Over Budget",IF($N10>$H10,"🔴 Projected Shortfall",IF($J10>=Controls!$C$8,"🟡 Watch","🟢 On Track"))))))) -> ⚪ No Funding on File
A11: =IF($B11="","",IF((IFERROR(INDEX(_RefTable!$A$2:$A$501,MATCH($B11,_RefTable!$C$2:$C$501,0)),IFERROR(INDEX(_MainTable!$A$2:$A$2001,MATCH($B11,_MainTable!$F$2:$F$2001,0)),IFERROR(INDEX('SC Change Orders'!$A$2:$A$501,MATCH($B11,'SC Change Orders'!$B$2:$B$501,0)),"(unknown vendor)"))))&""="","—",(IFERROR(INDEX(_RefTable!$A$2:$A$501,MATCH($B11,_RefTable!$C$2:$C$501,0)),IFERROR(INDEX(_MainTable!$A$2:$A$2001,MATCH($B11,_MainTable!$F$2:$F$2001,0)),IFERROR(INDEX('SC Change Orders'!$A$2:$A$501,MATCH($B11,'SC Change Orders'!$B$2:$B$501,0)),"(unknown vendor)")))))) -> ETYON | B11: =IFERROR(INDEX('PO Index'!$B$5:$B$84,7),"") -> 7927 | C11: =IF($B11="","",IF((IFERROR(INDEX(_RefTable!$B$2:$B$501,MATCH($B11,_RefTable!$C$2:$C$501,0))&IF(COUNTIF(_RefTable!$C$2:$C$501,$B11)>1," (+"&COUNTIF(_RefTable!$C$2:$C$501,$B11)-1&" more)",""),IFERROR(INDEX(_MainTable!$B$2:$B$2001,MATCH($B11,_MainTable!$F$2:$F$2001,0)),"")))&""="","—",(IFERROR(INDEX(_RefTable!$B$2:$B$501,MATCH($B11,_RefTable!$C$2:$C$501,0))&IF(COUNTIF(_RefTable!$C$2:$C$501,$B11)>1," (+"&COUNTIF(_RefTable!$C$2:$C$501,$B11)-1&" more)",""),IFERROR(INDEX(_MainTable!$B$2:$B$2001,MATCH($B11,_MainTable!$F$2:$F$2001,0)),""))))) -> Analytics | D11: =IF($B11="","",IF((IFERROR(INDEX(_RefTable!$E$2:$E$501,MATCH($B11,_RefTable!$C$2:$C$501,0)),IFERROR(INDEX(_MainTable!$C$2:$C$2001,MATCH($B11,_MainTable!$F$2:$F$2001,0)),"")))&""="","—",(IFERROR(INDEX(_RefTable!$E$2:$E$501,MATCH($B11,_RefTable!$C$2:$C$501,0)),IFERROR(INDEX(_MainTable!$C$2:$C$2001,MATCH($B11,_MainTable!$F$2:$F$2001,0)),""))))) -> Matt Morishita | E11: =IF($B11="","",IF((IFERROR(INDEX(_RefTable!$F$2:$F$501,MATCH($B11,_RefTable!$C$2:$C$501,0)),IFERROR(INDEX(_MainTable!$D$2:$D$2001,MATCH($B11,_MainTable!$F$2:$F$2001,0)),"")))&""="","—",(IFERROR(INDEX(_RefTable!$F$2:$F$501,MATCH($B11,_RefTable!$C$2:$C$501,0)),IFERROR(INDEX(_MainTable!$D$2:$D$2001,MATCH($B11,_MainTable!$F$2:$F$2001,0)),""))))) -> Amanda Leroue | F11: =IF($B11="","",IFERROR(_xlfn.MINIFS('SC Change Orders'!$E$2:$E$501,'SC Change Orders'!$B$2:$B$501,$B11,'SC Change Orders'!$C$2:$C$501,">="&Controls!$C$5,'SC Change Orders'!$C$2:$C$501,"<="&Controls!$C$6),0)) -> 0 | G11: =IF($B11="","",SUMIFS('SC Change Orders'!$F$2:$F$501,'SC Change Orders'!$B$2:$B$501,$B11,'SC Change Orders'!$C$2:$C$501,">="&Controls!$C$5,'SC Change Orders'!$C$2:$C$501,"<="&Controls!$C$6)) -> 0 | H11: =IF($B11="","",$F11+$G11) -> 0 | I11: =IF($B11="","",SUMIFS(_MainTable!$K$2:$K$2001,_MainTable!$F$2:$F$2001,$B11,_MainTable!$G$2:$G$2001,">="&Controls!$C$5,_MainTable!$G$2:$G$2001,"<="&Controls!$C$6)) -> 39026 | J11: =IF($B11="","",IFERROR($I11/$H11,0)) -> 0 | K11: =IF($B11="","",$H11-$I11) -> -39026 | L11: =IF($B11="","",IFERROR(SUMIFS(_MainTable!$K$2:$K$2001,_MainTable!$F$2:$F$2001,$B11,_MainTable!$G$2:$G$2001,">="&Controls!$C$12,_MainTable!$G$2:$G$2001,"<="&EOMONTH(Controls!$C$7,0))/MIN(Controls!$C$9,Controls!$C$10),0)) -> 9756.5 | M11: =IF($B11="","",$L11*Controls!$C$11) -> 19513 | N11: =IF($B11="","",$I11+$M11) -> 58539 | O11: =IF($B11="","",IFERROR($N11/$H11,0)) -> 0 | P11: =IF($B11="","",$H11-$N11) -> -58539 | Q11: =IF($B11="","",IF($L11<=0,"n/a",IFERROR($K11/$L11,"n/a"))) -> -4 | R11: =IF($B11="","",IF(AND($H11=0,$I11=0),"⚪ No Activity",IF(AND($H11=0,COUNTIFS('SC Change Orders'!$B$2:$B$501,$B11,'SC Change Orders'!$C$2:$C$501,">="&Controls!$C$5,'SC Change Orders'!$C$2:$C$501,"<="&Controls!$C$6)=0),"⚪ No Funding on File",IF($H11=0,"🔴 Unfunded Spend",IF($I11>=$H11,"🔴 Over Budget",IF($N11>$H11,"🔴 Projected Shortfall",IF($J11>=Controls!$C$8,"🟡 Watch","🟢 On Track"))))))) -> ⚪ No Funding on File
A12: =IF($B12="","",IF((IFERROR(INDEX(_RefTable!$A$2:$A$501,MATCH($B12,_RefTable!$C$2:$C$501,0)),IFERROR(INDEX(_MainTable!$A$2:$A$2001,MATCH($B12,_MainTable!$F$2:$F$2001,0)),IFERROR(INDEX('SC Change Orders'!$A$2:$A$501,MATCH($B12,'SC Change Orders'!$B$2:$B$501,0)),"(unknown vendor)"))))&""="","—",(IFERROR(INDEX(_RefTable!$A$2:$A$501,MATCH($B12,_RefTable!$C$2:$C$501,0)),IFERROR(INDEX(_MainTable!$A$2:$A$2001,MATCH($B12,_MainTable!$F$2:$F$2001,0)),IFERROR(INDEX('SC Change Orders'!$A$2:$A$501,MATCH($B12,'SC Change Orders'!$B$2:$B$501,0)),"(unknown vendor)")))))) -> HEALTHFUSE LLC | B12: =IFERROR(INDEX('PO Index'!$B$5:$B$84,8),"") -> 8438 | C12: =IF($B12="","",IF((IFERROR(INDEX(_RefTable!$B$2:$B$501,MATCH($B12,_RefTable!$C$2:$C$501,0))&IF(COUNTIF(_RefTable!$C$2:$C$501,$B12)>1," (+"&COUNTIF(_RefTable!$C$2:$C$501,$B12)-1&" more)",""),IFERROR(INDEX(_MainTable!$B$2:$B$2001,MATCH($B12,_MainTable!$F$2:$F$2001,0)),"")))&""="","—",(IFERROR(INDEX(_RefTable!$B$2:$B$501,MATCH($B12,_RefTable!$C$2:$C$501,0))&IF(COUNTIF(_RefTable!$C$2:$C$501,$B12)>1," (+"&COUNTIF(_RefTable!$C$2:$C$501,$B12)-1&" more)",""),IFERROR(INDEX(_MainTable!$B$2:$B$2001,MATCH($B12,_MainTable!$F$2:$F$2001,0)),""))))) -> Consultation | D12: =IF($B12="","",IF((IFERROR(INDEX(_RefTable!$E$2:$E$501,MATCH($B12,_RefTable!$C$2:$C$501,0)),IFERROR(INDEX(_MainTable!$C$2:$C$2001,MATCH($B12,_MainTable!$F$2:$F$2001,0)),"")))&""="","—",(IFERROR(INDEX(_RefTable!$E$2:$E$501,MATCH($B12,_RefTable!$C$2:$C$501,0)),IFERROR(INDEX(_MainTable!$C$2:$C$2001,MATCH($B12,_MainTable!$F$2:$F$2001,0)),""))))) -> Adam Vardaman | E12: =IF($B12="","",IF((IFERROR(INDEX(_RefTable!$F$2:$F$501,MATCH($B12,_RefTable!$C$2:$C$501,0)),IFERROR(INDEX(_MainTable!$D$2:$D$2001,MATCH($B12,_MainTable!$F$2:$F$2001,0)),"")))&""="","—",(IFERROR(INDEX(_RefTable!$F$2:$F$501,MATCH($B12,_RefTable!$C$2:$C$501,0)),IFERROR(INDEX(_MainTable!$D$2:$D$2001,MATCH($B12,_MainTable!$F$2:$F$2001,0)),""))))) -> — | F12: =IF($B12="","",IFERROR(_xlfn.MINIFS('SC Change Orders'!$E$2:$E$501,'SC Change Orders'!$B$2:$B$501,$B12,'SC Change Orders'!$C$2:$C$501,">="&Controls!$C$5,'SC Change Orders'!$C$2:$C$501,"<="&Controls!$C$6),0)) -> 0 | G12: =IF($B12="","",SUMIFS('SC Change Orders'!$F$2:$F$501,'SC Change Orders'!$B$2:$B$501,$B12,'SC Change Orders'!$C$2:$C$501,">="&Controls!$C$5,'SC Change Orders'!$C$2:$C$501,"<="&Controls!$C$6)) -> 0 | H12: =IF($B12="","",$F12+$G12) -> 0 | I12: =IF($B12="","",SUMIFS(_MainTable!$K$2:$K$2001,_MainTable!$F$2:$F$2001,$B12,_MainTable!$G$2:$G$2001,">="&Controls!$C$5,_MainTable!$G$2:$G$2001,"<="&Controls!$C$6)) -> 218875 | J12: =IF($B12="","",IFERROR($I12/$H12,0)) -> 0 | K12: =IF($B12="","",$H12-$I12) -> -218875 | L12: =IF($B12="","",IFERROR(SUMIFS(_MainTable!$K$2:$K$2001,_MainTable!$F$2:$F$2001,$B12,_MainTable!$G$2:$G$2001,">="&Controls!$C$12,_MainTable!$G$2:$G$2001,"<="&EOMONTH(Controls!$C$7,0))/MIN(Controls!$C$9,Controls!$C$10),0)) -> 43775 | M12: =IF($B12="","",$L12*Controls!$C$11) -> 87550 | N12: =IF($B12="","",$I12+$M12) -> 306425 | O12: =IF($B12="","",IFERROR($N12/$H12,0)) -> 0 | P12: =IF($B12="","",$H12-$N12) -> -306425 | Q12: =IF($B12="","",IF($L12<=0,"n/a",IFERROR($K12/$L12,"n/a"))) -> -5 | R12: =IF($B12="","",IF(AND($H12=0,$I12=0),"⚪ No Activity",IF(AND($H12=0,COUNTIFS('SC Change Orders'!$B$2:$B$501,$B12,'SC Change Orders'!$C$2:$C$501,">="&Controls!$C$5,'SC Change Orders'!$C$2:$C$501,"<="&Controls!$C$6)=0),"⚪ No Funding on File",IF($H12=0,"🔴 Unfunded Spend",IF($I12>=$H12,"🔴 Over Budget",IF($N12>$H12,"🔴 Projected Shortfall",IF($J12>=Controls!$C$8,"🟡 Watch","🟢 On Track"))))))) -> ⚪ No Funding on File
A13: =IF($B13="","",IF((IFERROR(INDEX(_RefTable!$A$2:$A$501,MATCH($B13,_RefTable!$C$2:$C$501,0)),IFERROR(INDEX(_MainTable!$A$2:$A$2001,MATCH($B13,_MainTable!$F$2:$F$2001,0)),IFERROR(INDEX('SC Change Orders'!$A$2:$A$501,MATCH($B13,'SC Change Orders'!$B$2:$B$501,0)),"(unknown vendor)"))))&""="","—",(IFERROR(INDEX(_RefTable!$A$2:$A$501,MATCH($B13,_RefTable!$C$2:$C$501,0)),IFERROR(INDEX(_MainTable!$A$2:$A$2001,MATCH($B13,_MainTable!$F$2:$F$2001,0)),IFERROR(INDEX('SC Change Orders'!$A$2:$A$501,MATCH($B13,'SC Change Orders'!$B$2:$B$501,0)),"(unknown vendor)")))))) -> CLOUDMED | B13: =IFERROR(INDEX('PO Index'!$B$5:$B$84,9),"") -> 8658 | C13: =IF($B13="","",IF((IFERROR(INDEX(_RefTable!$B$2:$B$501,MATCH($B13,_RefTable!$C$2:$C$501,0))&IF(COUNTIF(_RefTable!$C$2:$C$501,$B13)>1," (+"&COUNTIF(_RefTable!$C$2:$C$501,$B13)-1&" more)",""),IFERROR(INDEX(_MainTable!$B$2:$B$2001,MATCH($B13,_MainTable!$F$2:$F$2001,0)),"")))&""="","—",(IFERROR(INDEX(_RefTable!$B$2:$B$501,MATCH($B13,_RefTable!$C$2:$C$501,0))&IF(COUNTIF(_RefTable!$C$2:$C$501,$B13)>1," (+"&COUNTIF(_RefTable!$C$2:$C$501,$B13)-1&" more)",""),IFERROR(INDEX(_MainTable!$B$2:$B$2001,MATCH($B13,_MainTable!$F$2:$F$2001,0)),""))))) -> Charge Capture | D13: =IF($B13="","",IF((IFERROR(INDEX(_RefTable!$E$2:$E$501,MATCH($B13,_RefTable!$C$2:$C$501,0)),IFERROR(INDEX(_MainTable!$C$2:$C$2001,MATCH($B13,_MainTable!$F$2:$F$2001,0)),"")))&""="","—",(IFERROR(INDEX(_RefTable!$E$2:$E$501,MATCH($B13,_RefTable!$C$2:$C$501,0)),IFERROR(INDEX(_MainTable!$C$2:$C$2001,MATCH($B13,_MainTable!$F$2:$F$2001,0)),""))))) -> Sona Buchanan | E13: =IF($B13="","",IF((IFERROR(INDEX(_RefTable!$F$2:$F$501,MATCH($B13,_RefTable!$C$2:$C$501,0)),IFERROR(INDEX(_MainTable!$D$2:$D$2001,MATCH($B13,_MainTable!$F$2:$F$2001,0)),"")))&""="","—",(IFERROR(INDEX(_RefTable!$F$2:$F$501,MATCH($B13,_RefTable!$C$2:$C$501,0)),IFERROR(INDEX(_MainTable!$D$2:$D$2001,MATCH($B13,_MainTable!$F$2:$F$2001,0)),""))))) -> Heather Geile | F13: =IF($B13="","",IFERROR(_xlfn.MINIFS('SC Change Orders'!$E$2:$E$501,'SC Change Orders'!$B$2:$B$501,$B13,'SC Change Orders'!$C$2:$C$501,">="&Controls!$C$5,'SC Change Orders'!$C$2:$C$501,"<="&Controls!$C$6),0)) -> 250000 | G13: =IF($B13="","",SUMIFS('SC Change Orders'!$F$2:$F$501,'SC Change Orders'!$B$2:$B$501,$B13,'SC Change Orders'!$C$2:$C$501,">="&Controls!$C$5,'SC Change Orders'!$C$2:$C$501,"<="&Controls!$C$6)) -> 190000 | H13: =IF($B13="","",$F13+$G13) -> 440000 | I13: =IF($B13="","",SUMIFS(_MainTable!$K$2:$K$2001,_MainTable!$F$2:$F$2001,$B13,_MainTable!$G$2:$G$2001,">="&Controls!$C$5,_MainTable!$G$2:$G$2001,"<="&Controls!$C$6)) -> 80970.97 | J13: =IF($B13="","",IFERROR($I13/$H13,0)) -> 0.18402493 | K13: =IF($B13="","",$H13-$I13) -> 359029.03 | L13: =IF($B13="","",IFERROR(SUMIFS(_MainTable!$K$2:$K$2001,_MainTable!$F$2:$F$2001,$B13,_MainTable!$G$2:$G$2001,">="&Controls!$C$12,_MainTable!$G$2:$G$2001,"<="&EOMONTH(Controls!$C$7,0))/MIN(Controls!$C$9,Controls!$C$10),0)) -> 16519.443 | M13: =IF($B13="","",$L13*Controls!$C$11) -> 33038.887 | N13: =IF($B13="","",$I13+$M13) -> 114009.86 | O13: =IF($B13="","",IFERROR($N13/$H13,0)) -> 0.25911331 | P13: =IF($B13="","",$H13-$N13) -> 325990.14 | Q13: =IF($B13="","",IF($L13<=0,"n/a",IFERROR($K13/$L13,"n/a"))) -> 21.733724 | R13: =IF($B13="","",IF(AND($H13=0,$I13=0),"⚪ No Activity",IF(AND($H13=0,COUNTIFS('SC Change Orders'!$B$2:$B$501,$B13,'SC Change Orders'!$C$2:$C$501,">="&Controls!$C$5,'SC Change Orders'!$C$2:$C$501,"<="&Controls!$C$6)=0),"⚪ No Funding on File",IF($H13=0,"🔴 Unfunded Spend",IF($I13>=$H13,"🔴 Over Budget",IF($N13>$H13,"🔴 Projected Shortfall",IF($J13>=Controls!$C$8,"🟡 Watch","🟢 On Track"))))))) -> 🟢 On Track
A14: =IF($B14="","",IF((IFERROR(INDEX(_RefTable!$A$2:$A$501,MATCH($B14,_RefTable!$C$2:$C$501,0)),IFERROR(INDEX(_MainTable!$A$2:$A$2001,MATCH($B14,_MainTable!$F$2:$F$2001,0)),IFERROR(INDEX('SC Change Orders'!$A$2:$A$501,MATCH($B14,'SC Change Orders'!$B$2:$B$501,0)),"(unknown vendor)"))))&""="","—",(IFERROR(INDEX(_RefTable!$A$2:$A$501,MATCH($B14,_RefTable!$C$2:$C$501,0)),IFERROR(INDEX(_MainTable!$A$2:$A$2001,MATCH($B14,_MainTable!$F$2:$F$2001,0)),IFERROR(INDEX('SC Change Orders'!$A$2:$A$501,MATCH($B14,'SC Change Orders'!$B$2:$B$501,0)),"(unknown vendor)")))))) -> CLOUDMED | B14: =IFERROR(INDEX('PO Index'!$B$5:$B$84,10),"") -> 8659 | C14: =IF($B14="","",IF((IFERROR(INDEX(_RefTable!$B$2:$B$501,MATCH($B14,_RefTable!$C$2:$C$501,0))&IF(COUNTIF(_RefTable!$C$2:$C$501,$B14)>1," (+"&COUNTIF(_RefTable!$C$2:$C$501,$B14)-1&" more)",""),IFERROR(INDEX(_MainTable!$B$2:$B$2001,MATCH($B14,_MainTable!$F$2:$F$2001,0)),"")))&""="","—",(IFERROR(INDEX(_RefTable!$B$2:$B$501,MATCH($B14,_RefTable!$C$2:$C$501,0))&IF(COUNTIF(_RefTable!$C$2:$C$501,$B14)>1," (+"&COUNTIF(_RefTable!$C$2:$C$501,$B14)-1&" more)",""),IFERROR(INDEX(_MainTable!$B$2:$B$2001,MATCH($B14,_MainTable!$F$2:$F$2001,0)),""))))) -> DRG Validation | D14: =IF($B14="","",IF((IFERROR(INDEX(_RefTable!$E$2:$E$501,MATCH($B14,_RefTable!$C$2:$C$501,0)),IFERROR(INDEX(_MainTable!$C$2:$C$2001,MATCH($B14,_MainTable!$F$2:$F$2001,0)),"")))&""="","—",(IFERROR(INDEX(_RefTable!$E$2:$E$501,MATCH($B14,_RefTable!$C$2:$C$501,0)),IFERROR(INDEX(_MainTable!$C$2:$C$2001,MATCH($B14,_MainTable!$F$2:$F$2001,0)),""))))) -> Sona Buchanan | E14: =IF($B14="","",IF((IFERROR(INDEX(_RefTable!$F$2:$F$501,MATCH($B14,_RefTable!$C$2:$C$501,0)),IFERROR(INDEX(_MainTable!$D$2:$D$2001,MATCH($B14,_MainTable!$F$2:$F$2001,0)),"")))&""="","—",(IFERROR(INDEX(_RefTable!$F$2:$F$501,MATCH($B14,_RefTable!$C$2:$C$501,0)),IFERROR(INDEX(_MainTable!$D$2:$D$2001,MATCH($B14,_MainTable!$F$2:$F$2001,0)),""))))) -> Heather Geile | F14: =IF($B14="","",IFERROR(_xlfn.MINIFS('SC Change Orders'!$E$2:$E$501,'SC Change Orders'!$B$2:$B$501,$B14,'SC Change Orders'!$C$2:$C$501,">="&Controls!$C$5,'SC Change Orders'!$C$2:$C$501,"<="&Controls!$C$6),0)) -> 0 | G14: =IF($B14="","",SUMIFS('SC Change Orders'!$F$2:$F$501,'SC Change Orders'!$B$2:$B$501,$B14,'SC Change Orders'!$C$2:$C$501,">="&Controls!$C$5,'SC Change Orders'!$C$2:$C$501,"<="&Controls!$C$6)) -> 0 | H14: =IF($B14="","",$F14+$G14) -> 0 | I14: =IF($B14="","",SUMIFS(_MainTable!$K$2:$K$2001,_MainTable!$F$2:$F$2001,$B14,_MainTable!$G$2:$G$2001,">="&Controls!$C$5,_MainTable!$G$2:$G$2001,"<="&Controls!$C$6)) -> 106560.16 | J14: =IF($B14="","",IFERROR($I14/$H14,0)) -> 0 | K14: =IF($B14="","",$H14-$I14) -> -106560.16 | L14: =IF($B14="","",IFERROR(SUMIFS(_MainTable!$K$2:$K$2001,_MainTable!$F$2:$F$2001,$B14,_MainTable!$G$2:$G$2001,">="&Controls!$C$12,_MainTable!$G$2:$G$2001,"<="&EOMONTH(Controls!$C$7,0))/MIN(Controls!$C$9,Controls!$C$10),0)) -> 29782.7 | M14: =IF($B14="","",$L14*Controls!$C$11) -> 59565.4 | N14: =IF($B14="","",$I14+$M14) -> 166125.56 | O14: =IF($B14="","",IFERROR($N14/$H14,0)) -> 0 | P14: =IF($B14="","",$H14-$N14) -> -166125.56 | Q14: =IF($B14="","",IF($L14<=0,"n/a",IFERROR($K14/$L14,"n/a"))) -> -3.5779214 | R14: =IF($B14="","",IF(AND($H14=0,$I14=0),"⚪ No Activity",IF(AND($H14=0,COUNTIFS('SC Change Orders'!$B$2:$B$501,$B14,'SC Change Orders'!$C$2:$C$501,">="&Controls!$C$5,'SC Change Orders'!$C$2:$C$501,"<="&Controls!$C$6)=0),"⚪ No Funding on File",IF($H14=0,"🔴 Unfunded Spend",IF($I14>=$H14,"🔴 Over Budget",IF($N14>$H14,"🔴 Projected Shortfall",IF($J14>=Controls!$C$8,"🟡 Watch","🟢 On Track"))))))) -> ⚪ No Funding on File
A15: =IF($B15="","",IF((IFERROR(INDEX(_RefTable!$A$2:$A$501,MATCH($B15,_RefTable!$C$2:$C$501,0)),IFERROR(INDEX(_MainTable!$A$2:$A$2001,MATCH($B15,_MainTable!$F$2:$F$2001,0)),IFERROR(INDEX('SC Change Orders'!$A$2:$A$501,MATCH($B15,'SC Change Orders'!$B$2:$B$501,0)),"(unknown vendor)"))))&""="","—",(IFERROR(INDEX(_RefTable!$A$2:$A$501,MATCH($B15,_RefTable!$C$2:$C$501,0)),IFERROR(INDEX(_MainTable!$A$2:$A$2001,MATCH($B15,_MainTable!$F$2:$F$2001,0)),IFERROR(INDEX('SC Change Orders'!$A$2:$A$501,MATCH($B15,'SC Change Orders'!$B$2:$B$501,0)),"(unknown vendor)")))))) -> SOLVENTUM HEALTH INFO SYSTEM | B15: =IFERROR(INDEX('PO Index'!$B$5:$B$84,11),"") -> 9916 | C15: =IF($B15="","",IF((IFERROR(INDEX(_RefTable!$B$2:$B$501,MATCH($B15,_RefTable!$C$2:$C$501,0))&IF(COUNTIF(_RefTable!$C$2:$C$501,$B15)>1," (+"&COUNTIF(_RefTable!$C$2:$C$501,$B15)-1&" more)",""),IFERROR(INDEX(_MainTable!$B$2:$B$2001,MATCH($B15,_MainTable!$F$2:$F$2001,0)),"")))&""="","—",(IFERROR(INDEX(_RefTable!$B$2:$B$501,MATCH($B15,_RefTable!$C$2:$C$501,0))&IF(COUNTIF(_RefTable!$C$2:$C$501,$B15)>1," (+"&COUNTIF(_RefTable!$C$2:$C$501,$B15)-1&" more)",""),IFERROR(INDEX(_MainTable!$B$2:$B$2001,MATCH($B15,_MainTable!$F$2:$F$2001,0)),""))))) -> Inpatient CDI | D15: =IF($B15="","",IF((IFERROR(INDEX(_RefTable!$E$2:$E$501,MATCH($B15,_RefTable!$C$2:$C$501,0)),IFERROR(INDEX(_MainTable!$C$2:$C$2001,MATCH($B15,_MainTable!$F$2:$F$2001,0)),"")))&""="","—",(IFERROR(INDEX(_RefTable!$E$2:$E$501,MATCH($B15,_RefTable!$C$2:$C$501,0)),IFERROR(INDEX(_MainTable!$C$2:$C$2001,MATCH($B15,_MainTable!$F$2:$F$2001,0)),""))))) -> Sona Buchanan | E15: =IF($B15="","",IF((IFERROR(INDEX(_RefTable!$F$2:$F$501,MATCH($B15,_RefTable!$C$2:$C$501,0)),IFERROR(INDEX(_MainTable!$D$2:$D$2001,MATCH($B15,_MainTable!$F$2:$F$2001,0)),"")))&""="","—",(IFERROR(INDEX(_RefTable!$F$2:$F$501,MATCH($B15,_RefTable!$C$2:$C$501,0)),IFERROR(INDEX(_MainTable!$D$2:$D$2001,MATCH($B15,_MainTable!$F$2:$F$2001,0)),""))))) -> Janae Schumacher | F15: =IF($B15="","",IFERROR(_xlfn.MINIFS('SC Change Orders'!$E$2:$E$501,'SC Change Orders'!$B$2:$B$501,$B15,'SC Change Orders'!$C$2:$C$501,">="&Controls!$C$5,'SC Change Orders'!$C$2:$C$501,"<="&Controls!$C$6),0)) -> 0 | G15: =IF($B15="","",SUMIFS('SC Change Orders'!$F$2:$F$501,'SC Change Orders'!$B$2:$B$501,$B15,'SC Change Orders'!$C$2:$C$501,">="&Controls!$C$5,'SC Change Orders'!$C$2:$C$501,"<="&Controls!$C$6)) -> 0 | H15: =IF($B15="","",$F15+$G15) -> 0 | I15: =IF($B15="","",SUMIFS(_MainTable!$K$2:$K$2001,_MainTable!$F$2:$F$2001,$B15,_MainTable!$G$2:$G$2001,">="&Controls!$C$5,_MainTable!$G$2:$G$2001,"<="&Controls!$C$6)) -> 185499.25 | J15: =IF($B15="","",IFERROR($I15/$H15,0)) -> 0 | K15: =IF($B15="","",$H15-$I15) -> -185499.25 | L15: =IF($B15="","",IFERROR(SUMIFS(_MainTable!$K$2:$K$2001,_MainTable!$F$2:$F$2001,$B15,_MainTable!$G$2:$G$2001,">="&Controls!$C$12,_MainTable!$G$2:$G$2001,"<="&EOMONTH(Controls!$C$7,0))/MIN(Controls!$C$9,Controls!$C$10),0)) -> 0 | M15: =IF($B15="","",$L15*Controls!$C$11) -> 0 | N15: =IF($B15="","",$I15+$M15) -> 185499.25 | O15: =IF($B15="","",IFERROR($N15/$H15,0)) -> 0 | P15: =IF($B15="","",$H15-$N15) -> -185499.25 | Q15: =IF($B15="","",IF($L15<=0,"n/a",IFERROR($K15/$L15,"n/a"))) -> n/a | R15: =IF($B15="","",IF(AND($H15=0,$I15=0),"⚪ No Activity",IF(AND($H15=0,COUNTIFS('SC Change Orders'!$B$2:$B$501,$B15,'SC Change Orders'!$C$2:$C$501,">="&Controls!$C$5,'SC Change Orders'!$C$2:$C$501,"<="&Controls!$C$6)=0),"⚪ No Funding on File",IF($H15=0,"🔴 Unfunded Spend",IF($I15>=$H15,"🔴 Over Budget",IF($N15>$H15,"🔴 Projected Shortfall",IF($J15>=Controls!$C$8,"🟡 Watch","🟢 On Track"))))))) -> ⚪ No Funding on File
A16: =IF($B16="","",IF((IFERROR(INDEX(_RefTable!$A$2:$A$501,MATCH($B16,_RefTable!$C$2:$C$501,0)),IFERROR(INDEX(_MainTable!$A$2:$A$2001,MATCH($B16,_MainTable!$F$2:$F$2001,0)),IFERROR(INDEX('SC Change Orders'!$A$2:$A$501,MATCH($B16,'SC Change Orders'!$B$2:$B$501,0)),"(unknown vendor)"))))&""="","—",(IFERROR(INDEX(_RefTable!$A$2:$A$501,MATCH($B16,_RefTable!$C$2:$C$501,0)),IFERROR(INDEX(_MainTable!$A$2:$A$2001,MATCH($B16,_MainTable!$F$2:$F$2001,0)),IFERROR(INDEX('SC Change Orders'!$A$2:$A$501,MATCH($B16,'SC Change Orders'!$B$2:$B$501,0)),"(unknown vendor)")))))) -> TERNIUM LLC | B16: =IFERROR(INDEX('PO Index'!$B$5:$B$84,12),"") -> 10118 | C16: =IF($B16="","",IF((IFERROR(INDEX(_RefTable!$B$2:$B$501,MATCH($B16,_RefTable!$C$2:$C$501,0))&IF(COUNTIF(_RefTable!$C$2:$C$501,$B16)>1," (+"&COUNTIF(_RefTable!$C$2:$C$501,$B16)-1&" more)",""),IFERROR(INDEX(_MainTable!$B$2:$B$2001,MATCH($B16,_MainTable!$F$2:$F$2001,0)),"")))&""="","—",(IFERROR(INDEX(_RefTable!$B$2:$B$501,MATCH($B16,_RefTable!$C$2:$C$501,0))&IF(COUNTIF(_RefTable!$C$2:$C$501,$B16)>1," (+"&COUNTIF(_RefTable!$C$2:$C$501,$B16)-1&" more)",""),IFERROR(INDEX(_MainTable!$B$2:$B$2001,MATCH($B16,_MainTable!$F$2:$F$2001,0)),""))))) -> High dollar appeals | D16: =IF($B16="","",IF((IFERROR(INDEX(_RefTable!$E$2:$E$501,MATCH($B16,_RefTable!$C$2:$C$501,0)),IFERROR(INDEX(_MainTable!$C$2:$C$2001,MATCH($B16,_MainTable!$F$2:$F$2001,0)),"")))&""="","—",(IFERROR(INDEX(_RefTable!$E$2:$E$501,MATCH($B16,_RefTable!$C$2:$C$501,0)),IFERROR(INDEX(_MainTable!$C$2:$C$2001,MATCH($B16,_MainTable!$F$2:$F$2001,0)),""))))) -> Jake Reid | E16: =IF($B16="","",IF((IFERROR(INDEX(_RefTable!$F$2:$F$501,MATCH($B16,_RefTable!$C$2:$C$501,0)),IFERROR(INDEX(_MainTable!$D$2:$D$2001,MATCH($B16,_MainTable!$F$2:$F$2001,0)),"")))&""="","—",(IFERROR(INDEX(_RefTable!$F$2:$F$501,MATCH($B16,_RefTable!$C$2:$C$501,0)),IFERROR(INDEX(_MainTable!$D$2:$D$2001,MATCH($B16,_MainTable!$F$2:$F$2001,0)),""))))) -> Cody Thornock | F16: =IF($B16="","",IFERROR(_xlfn.MINIFS('SC Change Orders'!$E$2:$E$501,'SC Change Orders'!$B$2:$B$501,$B16,'SC Change Orders'!$C$2:$C$501,">="&Controls!$C$5,'SC Change Orders'!$C$2:$C$501,"<="&Controls!$C$6),0)) -> 0 | G16: =IF($B16="","",SUMIFS('SC Change Orders'!$F$2:$F$501,'SC Change Orders'!$B$2:$B$501,$B16,'SC Change Orders'!$C$2:$C$501,">="&Controls!$C$5,'SC Change Orders'!$C$2:$C$501,"<="&Controls!$C$6)) -> 0 | H16: =IF($B16="","",$F16+$G16) -> 0 | I16: =IF($B16="","",SUMIFS(_MainTable!$K$2:$K$2001,_MainTable!$F$2:$F$2001,$B16,_MainTable!$G$2:$G$2001,">="&Controls!$C$5,_MainTable!$G$2:$G$2001,"<="&Controls!$C$6)) -> 572803.83 | J16: =IF($B16="","",IFERROR($I16/$H16,0)) -> 0 | K16: =IF($B16="","",$H16-$I16) -> -572803.83 | L16: =IF($B16="","",IFERROR(SUMIFS(_MainTable!$K$2:$K$2001,_MainTable!$F$2:$F$2001,$B16,_MainTable!$G$2:$G$2001,">="&Controls!$C$12,_MainTable!$G$2:$G$2001,"<="&EOMONTH(Controls!$C$7,0))/MIN(Controls!$C$9,Controls!$C$10),0)) -> 126869.25 | M16: =IF($B16="","",$L16*Controls!$C$11) -> 253738.51 | N16: =IF($B16="","",$I16+$M16) -> 826542.34 | O16: =IF($B16="","",IFERROR($N16/$H16,0)) -> 0 | P16: =IF($B16="","",$H16-$N16) -> -826542.34 | Q16: =IF($B16="","",IF($L16<=0,"n/a",IFERROR($K16/$L16,"n/a"))) -> -4.5149145 | R16: =IF($B16="","",IF(AND($H16=0,$I16=0),"⚪ No Activity",IF(AND($H16=0,COUNTIFS('SC Change Orders'!$B$2:$B$501,$B16,'SC Change Orders'!$C$2:$C$501,">="&Controls!$C$5,'SC Change Orders'!$C$2:$C$501,"<="&Controls!$C$6)=0),"⚪ No Funding on File",IF($H16=0,"🔴 Unfunded Spend",IF($I16>=$H16,"🔴 Over Budget",IF($N16>$H16,"🔴 Projected Shortfall",IF($J16>=Controls!$C$8,"🟡 Watch","🟢 On Track"))))))) -> ⚪ No Funding on File
A17: =IF($B17="","",IF((IFERROR(INDEX(_RefTable!$A$2:$A$501,MATCH($B17,_RefTable!$C$2:$C$501,0)),IFERROR(INDEX(_MainTable!$A$2:$A$2001,MATCH($B17,_MainTable!$F$2:$F$2001,0)),IFERROR(INDEX('SC Change Orders'!$A$2:$A$501,MATCH($B17,'SC Change Orders'!$B$2:$B$501,0)),"(unknown vendor)"))))&""="","—",(IFERROR(INDEX(_RefTable!$A$2:$A$501,MATCH($B17,_RefTable!$C$2:$C$501,0)),IFERROR(INDEX(_MainTable!$A$2:$A$2001,MATCH($B17,_MainTable!$F$2:$F$2001,0)),IFERROR(INDEX('SC Change Orders'!$A$2:$A$501,MATCH($B17,'SC Change Orders'!$B$2:$B$501,0)),"(unknown vendor)")))))) -> EPIC ADVISORS GROUP LLC | B17: =IFERROR(INDEX('PO Index'!$B$5:$B$84,13),"") -> 10138 | C17: =IF($B17="","",IF((IFERROR(INDEX(_RefTable!$B$2:$B$501,MATCH($B17,_RefTable!$C$2:$C$501,0))&IF(COUNTIF(_RefTable!$C$2:$C$501,$B17)>1," (+"&COUNTIF(_RefTable!$C$2:$C$501,$B17)-1&" more)",""),IFERROR(INDEX(_MainTable!$B$2:$B$2001,MATCH($B17,_MainTable!$F$2:$F$2001,0)),"")))&""="","—",(IFERROR(INDEX(_RefTable!$B$2:$B$501,MATCH($B17,_RefTable!$C$2:$C$501,0))&IF(COUNTIF(_RefTable!$C$2:$C$501,$B17)>1," (+"&COUNTIF(_RefTable!$C$2:$C$501,$B17)-1&" more)",""),IFERROR(INDEX(_MainTable!$B$2:$B$2001,MATCH($B17,_MainTable!$F$2:$F$2001,0)),""))))) -> Consultation | D17: =IF($B17="","",IF((IFERROR(INDEX(_RefTable!$E$2:$E$501,MATCH($B17,_RefTable!$C$2:$C$501,0)),IFERROR(INDEX(_MainTable!$C$2:$C$2001,MATCH($B17,_MainTable!$F$2:$F$2001,0)),"")))&""="","—",(IFERROR(INDEX(_RefTable!$E$2:$E$501,MATCH($B17,_RefTable!$C$2:$C$501,0)),IFERROR(INDEX(_MainTable!$C$2:$C$2001,MATCH($B17,_MainTable!$F$2:$F$2001,0)),""))))) -> Michelle Lewis | E17: =IF($B17="","",IF((IFERROR(INDEX(_RefTable!$F$2:$F$501,MATCH($B17,_RefTable!$C$2:$C$501,0)),IFERROR(INDEX(_MainTable!$D$2:$D$2001,MATCH($B17,_MainTable!$F$2:$F$2001,0)),"")))&""="","—",(IFERROR(INDEX(_RefTable!$F$2:$F$501,MATCH($B17,_RefTable!$C$2:$C$501,0)),IFERROR(INDEX(_MainTable!$D$2:$D$2001,MATCH($B17,_MainTable!$F$2:$F$2001,0)),""))))) -> Adam Vardaman | F17: =IF($B17="","",IFERROR(_xlfn.MINIFS('SC Change Orders'!$E$2:$E$501,'SC Change Orders'!$B$2:$B$501,$B17,'SC Change Orders'!$C$2:$C$501,">="&Controls!$C$5,'SC Change Orders'!$C$2:$C$501,"<="&Controls!$C$6),0)) -> 72000 | G17: =IF($B17="","",SUMIFS('SC Change Orders'!$F$2:$F$501,'SC Change Orders'!$B$2:$B$501,$B17,'SC Change Orders'!$C$2:$C$501,">="&Controls!$C$5,'SC Change Orders'!$C$2:$C$501,"<="&Controls!$C$6)) -> 258295 | H17: =IF($B17="","",$F17+$G17) -> 330295 | I17: =IF($B17="","",SUMIFS(_MainTable!$K$2:$K$2001,_MainTable!$F$2:$F$2001,$B17,_MainTable!$G$2:$G$2001,">="&Controls!$C$5,_MainTable!$G$2:$G$2001,"<="&Controls!$C$6)) -> 119515.42 | J17: =IF($B17="","",IFERROR($I17/$H17,0)) -> 0.36184447 | K17: =IF($B17="","",$H17-$I17) -> 210779.58 | L17: =IF($B17="","",IFERROR(SUMIFS(_MainTable!$K$2:$K$2001,_MainTable!$F$2:$F$2001,$B17,_MainTable!$G$2:$G$2001,">="&Controls!$C$12,_MainTable!$G$2:$G$2001,"<="&EOMONTH(Controls!$C$7,0))/MIN(Controls!$C$9,Controls!$C$10),0)) -> 25215.473 | M17: =IF($B17="","",$L17*Controls!$C$11) -> 50430.947 | N17: =IF($B17="","",$I17+$M17) -> 169946.37 | O17: =IF($B17="","",IFERROR($N17/$H17,0)) -> 0.51452903 | P17: =IF($B17="","",$H17-$N17) -> 160348.63 | Q17: =IF($B17="","",IF($L17<=0,"n/a",IFERROR($K17/$L17,"n/a"))) -> 8.3591364 | R17: =IF($B17="","",IF(AND($H17=0,$I17=0),"⚪ No Activity",IF(AND($H17=0,COUNTIFS('SC Change Orders'!$B$2:$B$501,$B17,'SC Change Orders'!$C$2:$C$501,">="&Controls!$C$5,'SC Change Orders'!$C$2:$C$501,"<="&Controls!$C$6)=0),"⚪ No Funding on File",IF($H17=0,"🔴 Unfunded Spend",IF($I17>=$H17,"🔴 Over Budget",IF($N17>$H17,"🔴 Projected Shortfall",IF($J17>=Controls!$C$8,"🟡 Watch","🟢 On Track"))))))) -> 🟢 On Track
A18: =IF($B18="","",IF((IFERROR(INDEX(_RefTable!$A$2:$A$501,MATCH($B18,_RefTable!$C$2:$C$501,0)),IFERROR(INDEX(_MainTable!$A$2:$A$2001,MATCH($B18,_MainTable!$F$2:$F$2001,0)),IFERROR(INDEX('SC Change Orders'!$A$2:$A$501,MATCH($B18,'SC Change Orders'!$B$2:$B$501,0)),"(unknown vendor)"))))&""="","—",(IFERROR(INDEX(_RefTable!$A$2:$A$501,MATCH($B18,_RefTable!$C$2:$C$501,0)),IFERROR(INDEX(_MainTable!$A$2:$A$2001,MATCH($B18,_MainTable!$F$2:$F$2001,0)),IFERROR(INDEX('SC Change Orders'!$A$2:$A$501,MATCH($B18,'SC Change Orders'!$B$2:$B$501,0)),"(unknown vendor)")))))) -> ASPIRION HEALTH RESOURCES | B18: =IFERROR(INDEX('PO Index'!$B$5:$B$84,14),"") -> 10200 | C18: =IF($B18="","",IF((IFERROR(INDEX(_RefTable!$B$2:$B$501,MATCH($B18,_RefTable!$C$2:$C$501,0))&IF(COUNTIF(_RefTable!$C$2:$C$501,$B18)>1," (+"&COUNTIF(_RefTable!$C$2:$C$501,$B18)-1&" more)",""),IFERROR(INDEX(_MainTable!$B$2:$B$2001,MATCH($B18,_MainTable!$F$2:$F$2001,0)),"")))&""="","—",(IFERROR(INDEX(_RefTable!$B$2:$B$501,MATCH($B18,_RefTable!$C$2:$C$501,0))&IF(COUNTIF(_RefTable!$C$2:$C$501,$B18)>1," (+"&COUNTIF(_RefTable!$C$2:$C$501,$B18)-1&" more)",""),IFERROR(INDEX(_MainTable!$B$2:$B$2001,MATCH($B18,_MainTable!$F$2:$F$2001,0)),""))))) -> MVA (+1 more) | D18: =IF($B18="","",IF((IFERROR(INDEX(_RefTable!$E$2:$E$501,MATCH($B18,_RefTable!$C$2:$C$501,0)),IFERROR(INDEX(_MainTable!$C$2:$C$2001,MATCH($B18,_MainTable!$F$2:$F$2001,0)),"")))&""="","—",(IFERROR(INDEX(_RefTable!$E$2:$E$501,MATCH($B18,_RefTable!$C$2:$C$501,0)),IFERROR(INDEX(_MainTable!$C$2:$C$2001,MATCH($B18,_MainTable!$F$2:$F$2001,0)),""))))) -> Jake Reid | E18: =IF($B18="","",IF((IFERROR(INDEX(_RefTable!$F$2:$F$501,MATCH($B18,_RefTable!$C$2:$C$501,0)),IFERROR(INDEX(_MainTable!$D$2:$D$2001,MATCH($B18,_MainTable!$F$2:$F$2001,0)),"")))&""="","—",(IFERROR(INDEX(_RefTable!$F$2:$F$501,MATCH($B18,_RefTable!$C$2:$C$501,0)),IFERROR(INDEX(_MainTable!$D$2:$D$2001,MATCH($B18,_MainTable!$F$2:$F$2001,0)),""))))) -> Cody Thornock | F18: =IF($B18="","",IFERROR(_xlfn.MINIFS('SC Change Orders'!$E$2:$E$501,'SC Change Orders'!$B$2:$B$501,$B18,'SC Change Orders'!$C$2:$C$501,">="&Controls!$C$5,'SC Change Orders'!$C$2:$C$501,"<="&Controls!$C$6),0)) -> 92500 | G18: =IF($B18="","",SUMIFS('SC Change Orders'!$F$2:$F$501,'SC Change Orders'!$B$2:$B$501,$B18,'SC Change Orders'!$C$2:$C$501,">="&Controls!$C$5,'SC Change Orders'!$C$2:$C$501,"<="&Controls!$C$6)) -> 6353265.8 | H18: =IF($B18="","",$F18+$G18) -> 6445765.8 | I18: =IF($B18="","",SUMIFS(_MainTable!$K$2:$K$2001,_MainTable!$F$2:$F$2001,$B18,_MainTable!$G$2:$G$2001,">="&Controls!$C$5,_MainTable!$G$2:$G$2001,"<="&Controls!$C$6)) -> 4119364.1 | J18: =IF($B18="","",IFERROR($I18/$H18,0)) -> 0.63908063 | K18: =IF($B18="","",$H18-$I18) -> 2326401.8 | L18: =IF($B18="","",IFERROR(SUMIFS(_MainTable!$K$2:$K$2001,_MainTable!$F$2:$F$2001,$B18,_MainTable!$G$2:$G$2001,">="&Controls!$C$12,_MainTable!$G$2:$G$2001,"<="&EOMONTH(Controls!$C$7,0))/MIN(Controls!$C$9,Controls!$C$10),0)) -> 565165.09 | M18: =IF($B18="","",$L18*Controls!$C$11) -> 1130330.2 | N18: =IF($B18="","",$I18+$M18) -> 5249694.2 | O18: =IF($B18="","",IFERROR($N18/$H18,0)) -> 0.81444073 | P18: =IF($B18="","",$H18-$N18) -> 1196071.6 | Q18: =IF($B18="","",IF($L18<=0,"n/a",IFERROR($K18/$L18,"n/a"))) -> 4.1163225 | R18: =IF($B18="","",IF(AND($H18=0,$I18=0),"⚪ No Activity",IF(AND($H18=0,COUNTIFS('SC Change Orders'!$B$2:$B$501,$B18,'SC Change Orders'!$C$2:$C$501,">="&Controls!$C$5,'SC Change Orders'!$C$2:$C$501,"<="&Controls!$C$6)=0),"⚪ No Funding on File",IF($H18=0,"🔴 Unfunded Spend",IF($I18>=$H18,"🔴 Over Budget",IF($N18>$H18,"🔴 Projected Shortfall",IF($J18>=Controls!$C$8,"🟡 Watch","🟢 On Track"))))))) -> 🟢 On Track
A19: =IF($B19="","",IF((IFERROR(INDEX(_RefTable!$A$2:$A$501,MATCH($B19,_RefTable!$C$2:$C$501,0)),IFERROR(INDEX(_MainTable!$A$2:$A$2001,MATCH($B19,_MainTable!$F$2:$F$2001,0)),IFERROR(INDEX('SC Change Orders'!$A$2:$A$501,MATCH($B19,'SC Change Orders'!$B$2:$B$501,0)),"(unknown vendor)"))))&""="","—",(IFERROR(INDEX(_RefTable!$A$2:$A$501,MATCH($B19,_RefTable!$C$2:$C$501,0)),IFERROR(INDEX(_MainTable!$A$2:$A$2001,MATCH($B19,_MainTable!$F$2:$F$2001,0)),IFERROR(INDEX('SC Change Orders'!$A$2:$A$501,MATCH($B19,'SC Change Orders'!$B$2:$B$501,0)),"(unknown vendor)")))))) -> FINTHRIVE HEALTHCARE INC | B19: =IFERROR(INDEX('PO Index'!$B$5:$B$84,15),"") -> 10406 | C19: =IF($B19="","",IF((IFERROR(INDEX(_RefTable!$B$2:$B$501,MATCH($B19,_RefTable!$C$2:$C$501,0))&IF(COUNTIF(_RefTable!$C$2:$C$501,$B19)>1," (+"&COUNTIF(_RefTable!$C$2:$C$501,$B19)-1&" more)",""),IFERROR(INDEX(_MainTable!$B$2:$B$2001,MATCH($B19,_MainTable!$F$2:$F$2001,0)),"")))&""="","—",(IFERROR(INDEX(_RefTable!$B$2:$B$501,MATCH($B19,_RefTable!$C$2:$C$501,0))&IF(COUNTIF(_RefTable!$C$2:$C$501,$B19)>1," (+"&COUNTIF(_RefTable!$C$2:$C$501,$B19)-1&" more)",""),IFERROR(INDEX(_MainTable!$B$2:$B$2001,MATCH($B19,_MainTable!$F$2:$F$2001,0)),""))))) -> Transunion (+1 more) | D19: =IF($B19="","",IF((IFERROR(INDEX(_RefTable!$E$2:$E$501,MATCH($B19,_RefTable!$C$2:$C$501,0)),IFERROR(INDEX(_MainTable!$C$2:$C$2001,MATCH($B19,_MainTable!$F$2:$F$2001,0)),"")))&""="","—",(IFERROR(INDEX(_RefTable!$E$2:$E$501,MATCH($B19,_RefTable!$C$2:$C$501,0)),IFERROR(INDEX(_MainTable!$C$2:$C$2001,MATCH($B19,_MainTable!$F$2:$F$2001,0)),""))))) -> Sona Buchanan | E19: =IF($B19="","",IF((IFERROR(INDEX(_RefTable!$F$2:$F$501,MATCH($B19,_RefTable!$C$2:$C$501,0)),IFERROR(INDEX(_MainTable!$D$2:$D$2001,MATCH($B19,_MainTable!$F$2:$F$2001,0)),"")))&""="","—",(IFERROR(INDEX(_RefTable!$F$2:$F$501,MATCH($B19,_RefTable!$C$2:$C$501,0)),IFERROR(INDEX(_MainTable!$D$2:$D$2001,MATCH($B19,_MainTable!$F$2:$F$2001,0)),""))))) -> Tawnya Kraus | F19: =IF($B19="","",IFERROR(_xlfn.MINIFS('SC Change Orders'!$E$2:$E$501,'SC Change Orders'!$B$2:$B$501,$B19,'SC Change Orders'!$C$2:$C$501,">="&Controls!$C$5,'SC Change Orders'!$C$2:$C$501,"<="&Controls!$C$6),0)) -> 0 | G19: =IF($B19="","",SUMIFS('SC Change Orders'!$F$2:$F$501,'SC Change Orders'!$B$2:$B$501,$B19,'SC Change Orders'!$C$2:$C$501,">="&Controls!$C$5,'SC Change Orders'!$C$2:$C$501,"<="&Controls!$C$6)) -> 0 | H19: =IF($B19="","",$F19+$G19) -> 0 | I19: =IF($B19="","",SUMIFS(_MainTable!$K$2:$K$2001,_MainTable!$F$2:$F$2001,$B19,_MainTable!$G$2:$G$2001,">="&Controls!$C$5,_MainTable!$G$2:$G$2001,"<="&Controls!$C$6)) -> 4095.63 | J19: =IF($B19="","",IFERROR($I19/$H19,0)) -> 0 | K19: =IF($B19="","",$H19-$I19) -> -4095.63 | L19: =IF($B19="","",IFERROR(SUMIFS(_MainTable!$K$2:$K$2001,_MainTable!$F$2:$F$2001,$B19,_MainTable!$G$2:$G$2001,">="&Controls!$C$12,_MainTable!$G$2:$G$2001,"<="&EOMONTH(Controls!$C$7,0))/MIN(Controls!$C$9,Controls!$C$10),0)) -> 847.31 | M19: =IF($B19="","",$L19*Controls!$C$11) -> 1694.62 | N19: =IF($B19="","",$I19+$M19) -> 5790.25 | O19: =IF($B19="","",IFERROR($N19/$H19,0)) -> 0 | P19: =IF($B19="","",$H19-$N19) -> -5790.25 | Q19: =IF($B19="","",IF($L19<=0,"n/a",IFERROR($K19/$L19,"n/a"))) -> -4.8336854 | R19: =IF($B19="","",IF(AND($H19=0,$I19=0),"⚪ No Activity",IF(AND($H19=0,COUNTIFS('SC Change Orders'!$B$2:$B$501,$B19,'SC Change Orders'!$C$2:$C$501,">="&Controls!$C$5,'SC Change Orders'!$C$2:$C$501,"<="&Controls!$C$6)=0),"⚪ No Funding on File",IF($H19=0,"🔴 Unfunded Spend",IF($I19>=$H19,"🔴 Over Budget",IF($N19>$H19,"🔴 Projected Shortfall",IF($J19>=Controls!$C$8,"🟡 Watch","🟢 On Track"))))))) -> ⚪ No Funding on File
